<?xml version='1.0'?>
<sdf version='1.5'>
  <model name='uArm'>
    <pose>0 0 0.0169154 0 0 1.5707963</pose>

    <link name='base_link'>
      <inertial>
        <inertia>
          <ixx>8.431730</ixx>
          <ixy>-0.009720</ixy>
          <ixz>1.901570</ixz>
          <iyy>8.533050</iyy>
          <iyz>-0.007380</iyz>
          <izz>3.787470</izz>
        </inertia>
        <mass>118.00000</mass>
      </inertial>
      <visual name='visual'>
        <geometry>
          <mesh>
            <uri>model://uArm/meshes/base.dae</uri>
          </mesh>
        </geometry>
      </visual>
      <collision name='collision'>
        <pose>0 0 -0.0069154 0 0 0</pose>
        <geometry>
          <box>
            <size>0.19 0.19 0.02</size>
          </box>
        </geometry>
        <surface>
          <friction>
            <ode>
              <mu>500.000000</mu>
              <mu2>500.000000</mu2>
              <slip1>0.000000</slip1>
              <slip2>0.000000</slip2>
            </ode>
          </friction>
          <contact>
            <ode>
              <kp>1000000.000000</kp>
              <kd>1.000000</kd>
              <max_vel>100.000000</max_vel>
              <min_depth>0.000000</min_depth>
            </ode>
          </contact>
        </surface>
      </collision>
    </link>
    
    <link name='body_link'>
      <pose>0 0 0.0095 0 0 0</pose>
      <visual name='visual'>
        <pose>0 0 -0.0095 0 0 0.045719772</pose>
        <geometry>
          <mesh>
            <uri>model://uArm/meshes/body.dae</uri>
          </mesh>
        </geometry>
      </visual>
      <collision name='collision'>
        <pose>0 0 0.03 0 0 0</pose>
        <geometry>
          <box>
            <size>0.06 0.06 0.06</size>
          </box>
        </geometry>
      </collision>
    </link>
    <joint name="base_to_body" type="revolute">
      <child>body_link</child>
      <parent>base_link</parent>
      <axis>
        <limit>
          <lower>-1.5707963</lower>
          <upper>1.5707963</upper>
        </limit>
        <xyz>0 0 1</xyz>
      </axis>
    </joint>
  
    <link name='postarm_link'>
      <pose>0 -0.0215302 0.0895098 0 0 0</pose>
      <visual name='visual'>
        <pose>0 0.0215302 -0.0895098 0 0 0.045719772</pose>
        <geometry>
          <mesh>
            <uri>model://uArm/meshes/postarm.dae</uri>
          </mesh>
        </geometry>
      </visual>
      <collision name='collision'>
        <pose>0 0.03 0.07 -0.6 0 0</pose>
        <geometry>
          <box>
            <size>0.02 0.01 0.08</size>
          </box>
        </geometry>
      </collision>
    </link>
    <joint name="body_to_postarm" type="revolute">
      <child>postarm_link</child>
      <parent>body_link</parent>
      <axis>
        <limit>
          <lower>-0.1</lower>
          <upper>2.3</upper>
        </limit>
        <xyz>1 0 0</xyz>
      </axis>
    </joint>
  
    <link name='postarm_aux2_link'>
      <pose>-0.0083 -0.0215302 0.0895098 0 0 0</pose>
      <visual name='visual'>
        <pose>0.0083 0.0215302 -0.0895098 0 0 0.045719772</pose>
        <geometry>
          <mesh>
            <uri>model://uArm/meshes/postarm_aux2.dae</uri>
          </mesh>
        </geometry>
      </visual>
      <collision name='collision'>
        <pose>0 0.03 0.005 1.5707963 0 0</pose>
        <geometry>
          <box>
            <size>0.002 0.01 0.04</size>
          </box>
        </geometry>
      </collision>
    </link>
    <joint name="body_to_postarm_aux2" type="revolute">
      <child>postarm_aux2_link</child>
      <parent>body_link</parent>
      <axis>
        <limit>
          <lower>-2</lower>
          <upper>0.5</upper>
        </limit>
        <xyz>1 0 0</xyz>
      </axis>
    </joint>
  
    <link name='postarm_aux1_link'>
      <pose>-0.0083 0.0332492 0.0956167 0 0 0</pose>
      <visual name='visual'>
        <pose>0.0083 -0.0332492 -0.0956167 0 0 0.045719772</pose>
        <geometry>
          <mesh>
            <uri>model://uArm/meshes/postarm_aux1.dae</uri>
          </mesh>
        </geometry>
      </visual>
      <collision name='collision'>
        <pose>-0.003 0.05 0.07 -0.6 0 0</pose>
        <geometry>
          <box>
            <size>0.002 0.01 0.08</size>
          </box>
        </geometry>
      </collision>
    </link>
    <joint name="postarm_aux2_to_postarm_aux1" type="revolute">
      <child>postarm_aux1_link</child>
      <parent>postarm_aux2_link</parent>
      <axis>
        <xyz>1 0 0</xyz>
      </axis>
    </joint>
  
    <link name='forearm_link'>
      <pose>0 0.0584919 0.214727 0 0 0</pose>
      <visual name='visual'>
        <pose>0 -0.0584919 -0.214727 0 0 0.045719772</pose> <!-- (2.61955/180)*3.1415926 -->
        <geometry>
          <mesh>
            <uri>model://uArm/meshes/forearm.dae</uri>
          </mesh>
        </geometry>
      </visual>
      <collision name='collision'>
        <pose>0 -0.046 0.01 1.5707963 0 0</pose>
        <geometry>
          <box>
            <size>0.02 0.01 0.21</size>
          </box>
        </geometry>
      </collision>
    </link>
    <joint name="postarm_to_forearm" type="revolute">
      <child>forearm_link</child>
      <parent>postarm_link</parent>
      <axis>
        <xyz>1 0 0</xyz>
      </axis>
    </joint>
    
    <joint name="postarm_aux1_to_forearm" type="revolute">
      <child>forearm_link</child>
      <parent>postarm_aux1_link</parent>
      <pose>0 0.0536531 0.006107 0 0 0</pose>
      <axis>
        <xyz>1 0 0</xyz>
      </axis>
    </joint>
  
    <link name='postarm_aux3_link'>
      <pose>0.0165 0.014 0.1136 0 0 0</pose>
      <visual name='visual'>
        <pose>-0.0165 -0.014 -0.1136 0 0 0.045719772</pose>
        <geometry>
          <mesh>
            <uri>model://uArm/meshes/postarm_aux3.dae</uri>
          </mesh>
        </geometry>
      </visual>
      <collision name='collision'>
        <pose>0.002 0.045 0.07 -0.6 0 0</pose>
        <geometry>
          <box>
            <size>0.002 0.01 0.08</size>
          </box>
        </geometry>
      </collision>
    </link>
    <joint name="body_to_postarm_aux3" type="revolute">
      <child>postarm_aux3_link</child>
      <parent>body_link</parent>
      <axis>
        <xyz>1 0 0</xyz>
      </axis>
    </joint>
  
    <link name='triangle_link'>
      <pose>0.016 0.0584919 0.214727 0 0 0</pose>
      <visual name='visual'>
        <pose>-0.016 -0.0584919 -0.214727 0 0 0.045719772</pose>
        <geometry>
          <mesh>
            <uri>model://uArm/meshes/triangle.dae</uri>
          </mesh>
        </geometry>
      </visual>
      <collision name='collision'>
        <pose>-0.001 0 0.02 0 0 0</pose>
        <geometry>
          <box>
            <size>0.002 0.02 0.02</size>
          </box>
        </geometry>
      </collision>
    </link>
    <joint name="postarm_to_triangle" type="revolute">
      <child>triangle_link</child>
      <parent>postarm_link</parent>
      <axis>
        <xyz>1 0 0</xyz>
      </axis>
    </joint>
    
    <joint name="postarm_aux3_to_triangle" type="revolute">
      <child>triangle_link</child>
      <parent>postarm_aux3_link</parent>
      <pose>0 0.0344044 0.02409 0 0 0</pose>
      <axis>
        <xyz>1 0 0</xyz>
      </axis>
    </joint>
  
    <link name='forearm_aux_link'>
      <pose>0.0165 0.0240875 0.238817 0 0 0</pose>
      <visual name='visual'>
        <pose>-0.0165 -0.0240875 -0.238817 0 0 0.045719772</pose>
        <geometry>
          <mesh>
            <uri>model://uArm/meshes/forearm_aux.dae</uri>
          </mesh>
        </geometry>
      </visual>
      <collision name='collision'>
        <pose>0.002 -0.08 0 1.5707963 0 0</pose>
        <geometry>
          <box>
            <size>0.002 0.01 0.14</size>
          </box>
        </geometry>
      </collision>
    </link>
    <joint name="triangle_to_forearm_aux" type="revolute">
      <child>forearm_aux_link</child>
      <parent>triangle_link</parent>
      <axis>
        <xyz>1 0 0</xyz>
      </axis>
    </joint>
  
    <link name='hand_link'>
      <!--pose>0 -0.101499 0.205524 0 0 3.1415926</pose-->
      <pose>0 -0.101499 0.2164275 0 0 3.1415926</pose>
      <visual name='visual'>
        <pose>0 0.041 -0.0109035 0 0 0</pose>
        <geometry>
          <mesh>
            <uri>model://uArm/meshes/hand.dae</uri>
          </mesh>
        </geometry>
      </visual>
      <collision name='collision'>
        <pose>0 0.03 0 0 0 0</pose>
        <geometry>
          <box>
            <size>0.026 0.035 0.03</size>
          </box>
        </geometry>
      </collision>
    </link>
    <joint name="forearm_to_hand" type="revolute">
      <child>hand_link</child>
      <parent>forearm_link</parent>
      <axis>
        <xyz>1 0 0</xyz>
      </axis>
    </joint>
    
    <joint name="forearm_aux_to hand" type="revolute">
      <child>hand_link</child>
      <parent>forearm_aux_link</parent>
      <pose>-0.0165 0.0344 0.02409647 0 0 0</pose>
      <axis>
        <xyz>1 0 0</xyz>
      </axis>
    </joint>
  
    <link name='handrot_link'>
      <!--pose>0 -0.136040 0.166433 0 0 0</pose-->
      <pose>0 -0.136040 0.184433 0 0 0</pose>
      <visual name='visual'>
        <pose>0 0 -0.018 0 0 0</pose>
        <geometry>
          <mesh>
            <uri>model://uArm/meshes/handrot.dae</uri>
          </mesh>
        </geometry>
      </visual>
      <collision name='collision'>
        <pose>0 0 0.008 0 0 0</pose>
        <geometry>
          <box>
            <size>0.013 0.013 0.013</size>
          </box>
        </geometry>
      </collision>
    </link>
    <joint name="hand_to_handrot" type="revolute">
      <child>handrot_link</child>
      <parent>hand_link</parent>
      <axis>
        <limit>
          <lower>-0.8</lower>
          <upper>0.8</upper>
        </limit>
        <xyz>0 0 1</xyz>
      </axis>
    </joint>
  
    <link name='contact_link'>
      <pose>0 -0.136040 0.166433 0 0 0</pose>
      <visual name='visual'>
        <geometry>
          <mesh>
            <uri>model://uArm/meshes/contact.dae</uri>
          </mesh>
        </geometry>
      </visual>
      <collision name='collision'>
        <pose>0 0 0.012 0 0 0</pose>
        <geometry>
          <box>
            <size>0.015 0.015 0.01</size>
          </box>
        </geometry>
      </collision>
    </link>
    <joint name="handrot_to_contact" type="prismatic">
      <child>contact_link</child>
      <parent>handrot_link</parent>
      <axis>
        <limit>
          <lower>0</lower>
          <upper>0.002</upper>
        </limit>
        <xyz>0 0 1</xyz>
      </axis>
    </joint>
  
    <link name='sucker_link'>
      <!--pose>0 -0.136040 0.166433 1.5707963 0 0</pose-->
      <pose>0 -0.136040 0.174433 0 0 0</pose>
      <visual name='visual'>
        <pose>0 0 0 1.5707963 0 0</pose>
        <geometry>
          <mesh>
            <uri>model://uArm/meshes/sucker.dae</uri>
          </mesh>
        </geometry>
      </visual>
      <collision name='collision'>
        <pose>0 0 -0.012 0 0 0</pose>
        <geometry>
          <box>
            <size>0.015 0.015 0.01</size>
          </box>
        </geometry>
      </collision>
    </link>
    <joint name="contact_to_sucker" type="fixed">
      <child>sucker_link</child>
      <parent>contact_link</parent>
    </joint>
    
    <self_collide>0</self_collide>
    <static>0</static>
    <plugin name="uarm_plugin" filename="libUarmPlugin.so" />
  </model>
</sdf>

